Workbook
Name AGEPROG: 'AÇÕES E PROGRAMAS'!$A$2:$A$4
Name ARMBHPROG: 'AÇÕES E PROGRAMAS'!$B$2:$B$3
Name ARMVAPROG: 'AÇÕES E PROGRAMAS'!$C$2:$C$4
Name ARSAEPROG: 'AÇÕES E PROGRAMAS'!$E$2:$E$3
Name ARTEMIGPROG: 'AÇÕES E PROGRAMAS'!$DJ$2
Name CBMMGPROG: 'AÇÕES E PROGRAMAS'!$S$2:$S$5
Name CGEPROG: 'AÇÕES E PROGRAMAS'!$Q$2:$Q$6
Name DERPROG: 'AÇÕES E PROGRAMAS'!$U$2:$U$4
Name EAGE: AGRUPAMENTO!$C$115:$C$210
Name EGMG: AGRUPAMENTO!$C$2:$C$114
Name ELEMENTO: AGRUPAMENTO!$K$2:$K$267
Name EMATERPROG: 'AÇÕES E PROGRAMAS'!$X$2:$X$6
Name EMCPROG: 'AÇÕES E PROGRAMAS'!$Z$2:$Z$4
Name EOGE: AGRUPAMENTO!$C$211:$C$256
Name EPAMIGPROG: 'AÇÕES E PROGRAMAS'!$Y$2:$Y$4
Name EPMMG: AGRUPAMENTO!$C$575:$C$751
Name ESEAPA: AGRUPAMENTO!$C$475:$C$574
Name ESEDE: AGRUPAMENTO!$C$383:$C$474
Name ESEE: AGRUPAMENTO!$C$752:$C$948
Name ESEF: AGRUPAMENTO!$C$257:$C$382
Name ESPMGPROG: 'AÇÕES E PROGRAMAS'!$AB$2:$AB$3
Name FAOPPROG: 'AÇÕES E PROGRAMAS'!$AF$2:$AF$6
Name FAPEMIGPROG: 'AÇÕES E PROGRAMAS'!$AE$2:$AE$4
Name FCSPROG: 'AÇÕES E PROGRAMAS'!$AD$2:$AD$6
Name FDMPROG: 'AÇÕES E PROGRAMAS'!$AT$2
Name FEAMPROG: 'AÇÕES E PROGRAMAS'!$AI$2:$AI$4
Name FEASPROG: 'AÇÕES E PROGRAMAS'!$BE$2:$BE$3
Name FESPROG: 'AÇÕES E PROGRAMAS'!$BN$2:$BN$11
Name FGPPROG: 'AÇÕES E PROGRAMAS'!$AV$2
Name FHAPROG: 'AÇÕES E PROGRAMAS'!$AK$2:$AK$8
Name FHEMIGPROG: 'AÇÕES E PROGRAMAS'!$AL$2:$AL$3
Name FHIDROPROG: 'AÇÕES E PROGRAMAS'!$AZ$2:$AZ$6
Name FJPPROG: 'AÇÕES E PROGRAMAS'!$AM$2:$AM$6
Name FONTEARMBH: 'FONTE 1.0'!$A$2:$A$3
Name FONTEARMVA: 'FONTE 1.0'!$B$2:$B$3
Name FONTEARSAE: 'FONTE 1.0'!$C$2:$C$3
Name FONTEDER: 'FONTE 1.0'!$D$2:$D$10
Name FONTEFAOP: 'FONTE 1.0'!$F$2:$F$4
Name FONTEFCS: 'FONTE 1.0'!$G$2:$G$3
Name FONTEFDM: 'FONTE 1.0'!$R$2:$R$3
Name FONTEFEAM: 'FONTE 1.0'!$H$2:$H$5
Name FONTEFEAS: 'FONTE 1.0'!$S$2:$S$4
Name FONTEFJP: 'FONTE 1.0'!$I$2:$I$4
Name FONTEFUNTRANS: 'FONTE 1.0'!$E$2
Name FONTEIDENE: 'FONTE 1.0'!$J$2:$J$3
Name FONTEIEF: 'FONTE 1.0'!$K$2:$K$8
Name FONTEIEPHA: 'FONTE 1.0'!$L$2:$L$4
Name FONTEIGAM: 'FONTE 1.0'!$M$2:$M$6
Name FONTEIMA: 'FONTE 1.0'!$N$2:$N$4
Name FONTEJUCEMG: 'FONTE 1.0'!$O$2
Name FONTELEMG: 'FONTE 1.0'!$P$2
Name FONTESEDESE: 'FONTE 1.0'!$Q$2:$Q$7
Name FPPPROG: 'AÇÕES E PROGRAMAS'!$AY$2
Name FUCAMPROG: 'AÇÕES E PROGRAMAS'!$AH$2:$AH$4
Name FUNAPECPROG: 'AÇÕES E PROGRAMAS'!$AQ$2:$AQ$3
Name FUNEDPROG: 'AÇÕES E PROGRAMAS'!$AJ$2:$AJ$6
Name FUNTRANSPROG: 'AÇÕES E PROGRAMAS'!$BH$2:$BH$3
Name GMGPROG: 'AÇÕES E PROGRAMAS'!$BU$2:$BU$9
Name HEMOMINASPROG: 'AÇÕES E PROGRAMAS'!$AC$2:$AC$3
Name IDENEPROG: 'AÇÕES E PROGRAMAS'!$BW$2:$BW$4

Sheet INDICE
D7: ORÇAMENTO BASE ZERO (OBZ) 2026
B11: MATERIAL DE APOIO | D11: BASE OBZ | F11: MATERIAL DE APOIO
B12: CLASSIFICADOR ORÇAMENTÁRIO | F12: CONCEITOS METODOLÓGICOS IMPORTANTES
B13: DECRETO DIÁRIAS | D13: BASE OBZ - EXEMPLO

Sheet BASE OBZ - EXEMPLO
F1: INDICE | H1: PROJETO ORÇAMENTO BASE-ZERO
A2: UNIDADE ORÇAMENTÁRIA | B2: N2 | C2: SUB SIGLA | D2: N3 | E2: PROGRAMAUO | F2: PROGRAMA | G2: prog cod | H2: AÇÃO | I2: ELEMENTO | J2: ELEMENTO_ITEM | K2: Agrupamento | L2: GRUPO | M2: FONTEUO | N2: FONTE | O2: DESCRIÇÃO DO ITEM | P2: NOVO? | Q2: PREMISSA VOLUME | R2: VOLUME | S2: PREMISSA DE PREÇO | T2: PREÇO UNITÁRIO | U2: FREQUÊNCIA PAGAMENTO | V2: VALOR TOTAL ITEM | W2: CLASSIFICAÇÃO CENÁRIO | X2: DESCRIÇÃO DO CENÁRIO | Y2: RISCO DE NÃO FAZER | Z2: BENEFICIO AO FAZER | AA2: PRIORIDADE N3 | AB2: PRIORIDADE N2 | AC2: PRIORIDADE N1 | AD2: PRIORIDADE N2 | AE2: PRIORIDADE N1
A3: FAOP | B3: Subsecretaria de Promoção Cultural | D3: Superintendência de artes | E3: =CONCATENATE(A3,"PROG") -> FAOPPROG | F3: 060 - FORMACAO CULTURAL | G3: =CONCATENATE("P",(LEFT(F3,3)),A3) -> P060FAOP | H3: 1029 - ATIVIDADES DE ENSINO, FORMACAO E QUALIFICACAO PROFISSIONAL E TECNICA EM CULTURA E PATRIMONIO | I3: 1401 - DIÁRIAS CIVIL | J3: =CONCATENATE("ELEM",LEFT(#REF!,2)) -> #REF! | K3: Diárias e viagens | L3: 3 - Outras Despesas de Custeio | M3: =VLOOKUP(L3,#REF!,2,FALSE) -> #REF! | N3: 10 | O3: DIÁRIA PARA ATENDER HOSPEDAGEM DE PROFESSOR CONVIDADO PARA LECIONAR | P3: NÃO | Q3: NÚMERO DE DIÁRIAS UTILIZADAS (2) X NUMERO DE SERVIDORES FAVORECIDOS (1) | R3: 2 | S3: VALOR DA DIÁRIA DE ACORDO COM DECRETO 47.045/2016 (FAIXA 1 - MUNICÍPIO ESPECIAL) | T3: 294 | U3: 1 | V3: =R3*T3*U3 -> 588 | W3: LIMIAR | X3: REALIZAÇÃO DE CURSO COM APENAS UM PROFESSOR CONVIDADO | Y3: CURSO PRECISA DE PELO MENOS UM PROFESSOR PARA SER REALIZADO | Z3: NÃO É POSSÍVEL REALIZAR CURSO SEM PROFESSOR | AA3: CURSO PRECISA DE PELO MENOS UM PROFESSOR PARA SER REALIZADO | AB3: NÃO É POSSÍVEL REALIZAR CURSO SEM PROFESSOR
A4: FAOP | B4: Subsecretaria de Promoção Cultural | D4: Superintendência de artes | E4: =CONCATENATE(A4,"PROG") -> FAOPPROG | F4: 060 - FORMACAO CULTURAL | G4: =CONCATENATE("P",(LEFT(F4,3)),A4) -> P060FAOP | H4: 1029 - ATIVIDADES DE ENSINO, FORMACAO E QUALIFICACAO PROFISSIONAL E TECNICA EM CULTURA E PATRIMONIO | I4: 3301 - PASSAGENS - PESSOA FÍSICA | J4: =CONCATENATE("ELEM",LEFT(#REF!,2)) -> #REF! | K4: Diárias e viagens | L4: 3 - Outras Despesas de Custeio | M4: Diárias e viagens | N4: 10 | O4: PASSAGEM DE IDA E VOLTA PARA ATENDER DESLOCAMENTO DE PROFESSOR CONVIDADO PARA LECIONAR | P4: NÃO | Q4: 1 PASSAGEM DE IDA E VOLTA DE CONTAGEM PARA BH | R4: 1 | S4: VALOR DA PASSAGEM IDA E VOLTA | T4: 20 | U4: 1 | V4: =R4*T4*U4 -> 20 | W4: LIMIAR | X4: REALIZAÇÃO DE CURSO COM APENAS UM PROFESSOR CONVIDADO | Y4: CURSO PRECISA DE PELO MENOS UM PROFESSOR PARA SER REALIZADO | Z4: NÃO É POSSÍVEL REALIZAR CURSO SEM PROFESSOR | AA4: CURSO PRECISA DE PELO MENOS UM PROFESSOR PARA SER REALIZADO | AB4: NÃO É POSSÍVEL REALIZAR CURSO SEM PROFESSOR
A5: FAOP | B5: Subsecretaria de Promoção Cultural | D5: Superintendência de artes | E5: =CONCATENATE(A5,"PROG") -> FAOPPROG | F5: 060 - FORMACAO CULTURAL | G5: =CONCATENATE("P",(LEFT(F5,3)),A5) -> P060FAOP | H5: 1029 - ATIVIDADES DE ENSINO, FORMACAO E QUALIFICACAO PROFISSIONAL E TECNICA EM CULTURA E PATRIMONIO | I5: 1401 - DIÁRIAS CIVIL | J5: =CONCATENATE("ELEM",LEFT(#REF!,2)) -> #REF! | K5: Diárias e viagens | L5: 3 - Outras Despesas de Custeio | M5: Diárias e viagens | N5: 10 | O5: DIÁRIA PARA ATENDER HOSPEDAGEM DE PROFESSOR EXTRA CONVIDADO PARA LECIONAR | P5: SIM | Q5: NÚMERO DE DIÁRIAS UTILIZADAS (2) X NUMERO DE SERVIDORES FAVORECIDOS (1) | R5: 2 | S5: VALOR DA DIÁRIA DE ACORDO COM DECRETO 47.045/2016 (FAIXA 1 - MUNICÍPIO ESPECIAL) | T5: 294 | U5: 1 | V5: =R5*T5*U5 -> 588 | W5: LIMIAR | X5: CURSO MINISTRADO COM UM PROFESSOR EXTRA CONVIDADO | Y5: CURSO MENOS INTERESSANTE, MENOR CARGA HORÁRIO E POSSÍVEL MENOR ADESÃO DO PÚBLICO | Z5: CURSO COM MAIOR QUALIDADE E ADESÃO DO PÚBLICO | AA5: CURSO MENOS INTERESSANTE, MENOR CARGA HORÁRIO E POSSÍVEL MENOR ADESÃO DO PÚBLICO | AB5: CURSO COM MAIOR QUALIDADE E ADESÃO DO PÚBLICO
A6: FAOP | B6: Subsecretaria de Promoção Cultural | D6: Superintendência de artes | E6: =CONCATENATE(A6,"PROG") -> FAOPPROG | F6: 060 - FORMACAO CULTURAL | G6: =CONCATENATE("P",(LEFT(F6,3)),A6) -> P060FAOP | H6: 1029 - ATIVIDADES DE ENSINO, FORMACAO E QUALIFICACAO PROFISSIONAL E TECNICA EM CULTURA E PATRIMONIO | I6: 3301 - PASSAGENS - PESSOA FÍSICA | J6: =CONCATENATE("ELEM",LEFT(#REF!,2)) -> #REF! | K6: Diárias e viagens | L6: 3 - Outras Despesas de Custeio | M6: Diárias e viagens | N6: 10 | O6: PASSAGEM DE IDA E VOLTA PARA ATENDER DESLOCAMENTO DE PROFESSOR EXTRA CONVIDADO PARA LECIONAR | P6: SIM | Q6: 1 PASSAGEM DE IDA E VOLTA DE CONTAGEM PARA BH | R6: 1 | S6: VALOR DA PASSAGEM IDA E VOLTA | T6: 20 | U6: 1 | V6: =R6*T6*U6 -> 20 | W6: LIMIAR | X6: CURSO MINISTRADO COM UM PROFESSOR EXTRA CONVIDADO | Y6: CURSO MENOS INTERESSANTE, MENOR CARGA HORÁRIO E POSSÍVEL MENOR ADESÃO DO PÚBLICO | Z6: CURSO COM MAIOR QUALIDADE E ADESÃO DO PÚBLICO | AA6: CURSO MENOS INTERESSANTE, MENOR CARGA HORÁRIO E POSSÍVEL MENOR ADESÃO DO PÚBLICO | AB6: CURSO COM MAIOR QUALIDADE E ADESÃO DO PÚBLICO
A7: FAOP | B7: Subsecretaria de Promoção Cultural | D7: Superintendência de artes | E7: =CONCATENATE(A7,"PROG") -> FAOPPROG | F7: 060 - FORMACAO CULTURAL | G7: =CONCATENATE("P",(LEFT(F7,3)),A7) -> P060FAOP | H7: 1029 - ATIVIDADES DE ENSINO, FORMACAO E QUALIFICACAO PROFISSIONAL E TECNICA EM CULTURA E PATRIMONIO | I7: 3952 - CONTRATAÇÃO DE ESTAGIÁRIOS | J7: =CONCATENATE("ELEM",LEFT(#REF!,2)) -> #REF! | K7: Estagiários | L7: 3 - Outras Despesas de Custeio | M7: Estagiários | N7: 60 | O7: ESTAGIÁRIO CARGA HORÁRIA 30 HORAS SEMANAIS | P7: SIM | Q7: NÚMERO DE ESTAGIÁRIOS | R7: 2 | S7: VALOR DA BOLSA ESTAGIÁRIO + VALE TRANSPORTE | T7: 900 | U7: 12 | V7: =R7*T7*U7 -> 21600 | W7: INCREMENTAL | X7: EXPANSÃO DOS CURSOS PARA A MODALIDADE EAD | Y7: MAIOR DEMORA PARA A REALIZAÇÃO DOS PROCESSOS DE TESTE DA PLATAFORMA; CURSO MAIS DESORGANIZADO E ACÚMULO DE TAREFAS AOS SERVIDORES | Z7: PROCESSOS MAIS ÁGEIS; CURSO MAIS ORGANIZADO E SERVIDORES MENOS SOBRECARREGADOS | AA7: MAIOR DEMORA PARA A REALIZAÇÃO DOS PROCESSOS DE TESTE DA PLATAFORMA; CURSO MAIS DESORGANIZADO E ACÚMULO DE TAREFAS AOS SERVIDORES | AB7: PROCESSOS MAIS ÁGEIS; CURSO MAIS ORGANIZADO E SERVIDORES MENOS SOBRECARREGADOS | AC7: 3 | AD7: 3
A8: FAOP | B8: Subsecretaria de Promoção Cultural | D8: Superintendência de artes | E8: =CONCATENATE(A8,"PROG") -> FAOPPROG | F8: 060 - FORMACAO CULTURAL | G8: =CONCATENATE("P",(LEFT(F8,3)),A8) -> P060FAOP | H8: 1029 - ATIVIDADES DE ENSINO, FORMACAO E QUALIFICACAO PROFISSIONAL E TECNICA EM CULTURA E PATRIMONIO | I8: 3005 - MATERIAL PARA ESCRITÓRIO | J8: =CONCATENATE("ELEM",LEFT(#REF!,2)) -> #REF! | K8: Aquisição de material de consumo | L8: 3 - Outras Despesas de Custeio | M8: Aquisição de material de consumo | N8: 10 | O8: PACOTE DE FOLHA A4 BRANCA COM 100 UNIDADES | P8: NÃO | Q8: MÉDIA DE CONSUMO PARA UM CURSO DE 2 DIAS | R8: 1 | S8: CONSULTA DO VALOR DO ITEM NO SIAD | T8: 25 | U8: 1 | V8: =R8*T8*U8 -> 25 | W8: LIMIAR | X8: REALIZAÇÃO DE CURSO COM APENAS UM PROFESSOR CONVIDADO | Y8: ALUNOS PRECISAM DE FOLHA PARA REALIZAR AS ATIVIDADES AVALIATIVAS | Z8: NÃO É POSSÍVEL REALIZAR AS ATIVIDADES SEM QUE OS ALUNOS TENHAM ONDE ESCREVER AS RESPOSTAS | AA8: ALUNOS PRECISAM DE FOLHA PARA REALIZAR AS ATIVIDADES AVALIATIVAS | AB8: NÃO É POSSÍVEL REALIZAR AS ATIVIDADES SEM QUE OS ALUNOS TENHAM ONDE ESCREVER AS RESPOSTAS
A9: FAOP | B9: Subsecretaria de Promoção Cultural | D9: Superintendência de artes | E9: =CONCATENATE(A9,"PROG") -> FAOPPROG | F9: 060 - FORMACAO CULTURAL | G9: =CONCATENATE("P",(LEFT(F9,3)),A9) -> P060FAOP | H9: 1029 - ATIVIDADES DE ENSINO, FORMACAO E QUALIFICACAO PROFISSIONAL E TECNICA EM CULTURA E PATRIMONIO | I9: 3005 - MATERIAL PARA ESCRITÓRIO | J9: =CONCATENATE("ELEM",LEFT(#REF!,2)) -> #REF! | K9: Aquisição de material de consumo | L9: 3 - Outras Despesas de Custeio | M9: Aquisição de material de consumo | N9: 60 | O9: KIT DE MATERIAL PARA CURSO (CANETA ESFEROGRÁFICA AZUL, LÁPIS, BORRACHA) | P9: NÃO | Q9: 1 KIT POR PESSOA X MÉDIA DE INSCRIÇÕES NO CURSO (100) | R9: 100 | S9: CONSULTA DO VALOR DOS ITENS QUE COMPÕES O KIT NO SIAD | T9: 8 | U9: 1 | V9: =R9*T9*U9 -> 800 | W9: INCREMENTAL | X9: FORNECIMENTO DE ITENS DE SUPORTE AO PARTICIPANTE DOS CURSOS | Y9: MENOR ADESÃO AO CURSO DEVIDO AO PÚBLICO ALVO NÃO POSSUIR CONDIÇÕES FINANCEIRAS DE ADQUIRIR OS MATERIAIS DO KIT | Z9: MAIOR ADESÃO DO PÚBLICO ALVO E MELHOR DESEMPENHO DOS ALUNOS | AA9: MENOR ADESÃO AO CURSO DEVIDO AO PÚBLICO ALVO NÃO POSSUIR CONDIÇÕES FINANCEIRAS DE ADQUIRIR OS MATERIAIS DO KIT | AB9: MAIOR ADESÃO DO PÚBLICO ALVO E MELHOR DESEMPENHO DOS ALUNOS | AC9: 1 | AD9: 2
A10: FAOP | B10: Subsecretaria de Promoção Cultural | D10: Superintendência de artes | E10: =CONCATENATE(A10,"PROG") -> FAOPPROG | F10: 060 - FORMACAO CULTURAL | G10: =CONCATENATE("P",(LEFT(F10,3)),A10) -> P060FAOP | H10: 1029 - ATIVIDADES DE ENSINO, FORMACAO E QUALIFICACAO PROFISSIONAL E TECNICA EM CULTURA E PATRIMONIO | I10: 3903 - FORNECIMENTO DE ALIMENTAÇÃO | J10: =CONCATENATE("ELEM",LEFT(#REF!,2)) -> #REF! | K10: Alimentação | L10: 3 - Outras Despesas de Custeio | M10: Alimentação | N10: 60 | O10: FORNECIMENTO DE COFFEE BREAK PARA O CURSO | P10: SIM | Q10: CONTRATO FIRMADO | R10: 1 | S10: VALOR HISTÓRICO DOS CONTRADOS FIRMADOS | T10: 500 | U10: 1 | V10: =R10*T10*U10 -> 500 | W10: INCREMENTAL | X10: FORNECIMENTO DE ITENS DE SUPORTE AO PARTICIPANTE DOS CURSOS | Y10: POSSIBILIDADE DO PÚBLICO ALVO NÃO ADERIR AO CURSO POR QUESTÕES FINANCEIRAS QUE IMPOSSIBILITEM A AQUISIÇÃO DE LANCHE DURANTE O DIA; MAIOR TEMPO DE INTERVALO DURANTE O CURSO E MENOR ADESÃO DO PÚBLICO AO CURSO | Z10: CURSO MAIS ATRATIVO, GERANDO MAIOR ADESÃO DO PÚBLICO ALVO | AA10: POSSIBILIDADE DO PÚBLICO ALVO NÃO ADERIR AO CURSO POR QUESTÕES FINANCEIRAS QUE IMPOSSIBILITEM A AQUISIÇÃO DE LANCHE DURANTE O DIA; MAIOR TEMPO DE INTERVALO DURANTE O CURSO E MENOR ADESÃO DO PÚBLICO AO CURSO | AB10: CURSO MAIS ATRATIVO, GERANDO MAIOR ADESÃO DO PÚBLICO ALVO | AC10: 1 | AD10: 2
A11: FAOP | B11: Subsecretaria de Promoção Cultural | D11: Superintendência de artes | E11: =CONCATENATE(A11,"PROG") -> FAOPPROG | F11: 060 - FORMACAO CULTURAL | G11: =CONCATENATE("P",(LEFT(F11,3)),A11) -> P060FAOP | H11: 1029 - ATIVIDADES DE ENSINO, FORMACAO E QUALIFICACAO PROFISSIONAL E TECNICA EM CULTURA E PATRIMONIO | I11: 4007 - AQUISIÇÃO DE SOFTWARE DESENVOLVIDOS PELA PRODEMGE | J11: =CONCATENATE("ELEM",LEFT(#REF!,2)) -> #REF! | K11: PRODEMGE | L11: 4 - Investimento | M11: PRODEMGE | N11: 10 | O11: DESENVOLVIMENTO DE PLATAFORMA MOODLE PARA CURSO EAD | P11: SIM | Q11: CONTRATO FIRMADO | R11: 1 | S11: TABELA DE SERVIÇOS PRODEMGE | T11: 5000 | U11: 1 | V11: =R11*T11*U11 -> 5000 | W11: INCREMENTAL | X11: EXPANSÃO DOS CURSOS PARA A MODALIDADE EAD | Y11: MENOR PÚBLICO DEVIDO À OFERTA DE CURSOS SOMENTE NA MODALIDADE PRESENCIAL | Z11: ATINGIR MAIOR PÚBLICO | AA11: MENOR PÚBLICO DEVIDO À OFERTA DE CURSOS SOMENTE NA MODALIDADE PRESENCIAL | AB11: ATINGIR MAIOR PÚBLICO | AC11: 3 | AD11: 3
A12: FAOP | B12: Subsecretaria de Promoção Cultural | D12: Superintendência de artes | E12: =CONCATENATE(A12,"PROG") -> FAOPPROG | F12: 056 - FOMENTO, DEMOCRATIZACAO E ACESSO A CULTURA E AO TURISMO | G12: =CONCATENATE("P",(LEFT(F12,3)),A12) -> P056FAOP | H12: 1027 - ACOES DE DIFUSAO DAS ARTES E DO PATRIMONIO CULTURAL | I12: 3702 - LOCAÇÃO DE SERVIÇOS DE APOIO ADMINISTRATIVO | J12: =CONCATENATE("ELEM",LEFT(#REF!,2)) -> #REF! | K12: Demais terceirizados | L12: 3 - Outras Despesas de Custeio | M12: Demais terceirizados | N12: 10 | O12: POSTO DE TRABALHO DE SEGURANÇA 24H | P12: NÃO | Q12: CONTRATATO FIRMADO COM A EMPRESA "SECURITY" | R12: 1 | S12: VALOR MENSAL DO CONTRATO | T12: 2000 | U12: 12 | V12: =R12*T12*U12 -> 24000 | W12: LIMIAR | X12: SEGURANÇA MÍNIMA NECESSÁRIA PARA ATENDER A GUARDA DO MUSEU DURANTE 12H | Y12: AUSÊNCIA DE SEGURANÇA DO MUSEU, DEIXANDO O PRÉDIO COMPLETAMENTE VULNERÁVEL | Z12: REDUÇÃO DO RISCO DE DEPREDAÇÃO DO MUSEU | AA12: AUSÊNCIA DE SEGURANÇA DO MUSEU, DEIXANDO O PRÉDIO COMPLETAMENTE VULNERÁVEL | AB12: REDUÇÃO DO RISCO DE DEPREDAÇÃO DO MUSEU
A13: FAOP | B13: Subsecretaria de Promoção Cultural | D13: Superintendência de artes | E13: =CONCATENATE(A13,"PROG") -> FAOPPROG | F13: 056 - FOMENTO, DEMOCRATIZACAO E ACESSO A CULTURA E AO TURISMO | G13: =CONCATENATE("P",(LEFT(F13,3)),A13) -> P056FAOP | H13: 1027 - ACOES DE DIFUSAO DAS ARTES E DO PATRIMONIO CULTURAL | I13: 3702 - LOCAÇÃO DE SERVIÇOS DE APOIO ADMINISTRATIVO | J13: =CONCATENATE("ELEM",LEFT(#REF!,2)) -> #REF! | K13: Demais terceirizados | L13: 3 - Outras Despesas de Custeio | M13: Demais terceirizados | N13: 60 | O13: ADITIVO PARA SEGURANÇA 24 HORAS (ADICIONAL DE 1 SEGURANÇA) | P13: SIM | Q13: ADITIVO CONTRATUAL COM A EMPRESA "SECURITY" | R13: 1 | S13: VALOR MENSAL DO ADITIVO (NÚMERO DE POSTOS DE TRABALHO X VALOR DO POSTO) | T13: 2000 | U13: 12 | V13: =R13*T13*U13 -> 24000 | W13: LIMIAR | X13: AUMENTO DA SEGURANÇA DO MUSEU, VIABILIZANDO GUARDA NOS PERÍODOS DIURNO E NOTURNO | Y13: MAIOR RISCO DE DEPREDAÇÃO, VISTO QUE SÓ HÁ SEGURANÇA NO LOCAL DURANTE UM PERÍODO DO DIA | Z13: MAIOR SEGURANÇA NO PRÉDIO DA FUNDAÇÃO COM VIGILÂNCIA 24 HORAS | AA13: MAIOR RISCO DE DEPREDAÇÃO, VISTO QUE SÓ HÁ SEGURANÇA NO LOCAL DURANTE UM PERÍODO DO DIA | AB13: MAIOR SEGURANÇA NO PRÉDIO DA FUNDAÇÃO COM VIGILÂNCIA 24 HORAS
A14: FAOP | B14: Subsecretaria de Promoção Cultural | D14: Superintendência de artes | E14: =CONCATENATE(A14,"PROG") -> FAOPPROG | F14: 056 - FOMENTO, DEMOCRATIZACAO E ACESSO A CULTURA E AO TURISMO | G14: =CONCATENATE("P",(LEFT(F14,3)),A14) -> P056FAOP | H14: 1027 - ACOES DE DIFUSAO DAS ARTES E DO PATRIMONIO CULTURAL | I14: 3703 - LOCAÇÃO DE SERVIÇOS DE CONSERVAÇÃO E LIMPEZA REALIZADOS PELA MGS | J14: =CONCATENATE("ELEM",LEFT(#REF!,2)) -> #REF! | K14: Terceirizados - MGS | L14: 3 - Outras Despesas de Custeio | M14: Terceirizados - MGS | N14: 10 | O14: POSTO DE TRABALHO DE MANUTENÇÃO E LIMPEZA | P14: NÃO | Q14: NÚMERO DE POSTOS DE TRABALHO PARA MANUTENÇÃO DO MUSEU | R14: 3 | S14: VALOR MENSAL DO POSTO DE TRABALHO CONFORME CONTRATO | T14: 1500 | U14: 12 | V14: =R14*T14*U14 -> 54000 | W14: LIMIAR | X14: LIMPEZA EFETUADA DE TRÊS EM TRÊS HORAS NOS SALÕES DO MUSEU | Y14: SALÃO DO MUSEU PODE COM ACÚMULO DE SUJEIRA, GERANDO MÁ IMPRESSÃO AOS FREQUENTADORES E DINIMUINDO A VISITAÇÃO | Z14: MUSEU MINIMAMENTE LIMPO | AA14: SALÃO DO MUSEU PODE COM ACÚMULO DE SUJEIRA, GERANDO MÁ IMPRESSÃO AOS FREQUENTADORES E DINIMUINDO A VISITAÇÃO | AB14: MUSEU MINIMAMENTE LIMPO
A15: FAOP | B15: Subsecretaria de Promoção Cultural | D15: Superintendência de artes | E15: =CONCATENATE(A15,"PROG") -> FAOPPROG | F15: 056 - FOMENTO, DEMOCRATIZACAO E ACESSO A CULTURA E AO TURISMO | G15: =CONCATENATE("P",(LEFT(F15,3)),A15) -> P056FAOP | H15: 1027 - ACOES DE DIFUSAO DAS ARTES E DO PATRIMONIO CULTURAL | I15: 3703 - LOCAÇÃO DE SERVIÇOS DE CONSERVAÇÃO E LIMPEZA REALIZADOS PELA MGS | J15: =CONCATENATE("ELEM",LEFT(#REF!,2)) -> #REF! | K15: Terceirizados - MGS | L15: 3 - Outras Despesas de Custeio | M15: Terceirizados - MGS | N15: 60 | O15: POSTO DE TRABALHO DE MANUTENÇÃO E LIMPEZA | P15: SIM | Q15: NÚMERO DE POSTOS DE TRABALHO PARA MANUTENÇÃO DO MUSEU | R15: 2 | S15: VALOR MENSAL DO POSTO DE TRABALHO CONFORME CONTRATO | T15: 1500 | U15: 12 | V15: =R15*T15*U15 -> 36000 | W15: INCREMENTAL | X15: LIMPEZA EFETUADA DE HORA EM HORA NOS SALÕES DO MUSEU | Y15: SALÃO DO MUSEU PODE FICAR SUJO ENTRE UMA E OUTRA VISITA, GERANDO INSATISFAÇÃO DOS FREQUENTADORES | Z15: MUSEU MAIS LIMPO, USUÁRIOS SATISFEITOS E MAIOR VISITAÇÃO | AA15: SALÃO DO MUSEU PODE FICAR SUJO ENTRE UMA E OUTRA VISITA, GERANDO INSATISFAÇÃO DOS FREQUENTADORES | AB15: MUSEU MAIS LIMPO, USUÁRIOS SATISFEITOS E MAIOR VISITAÇÃO | AC15: 2 | AD15: 1
E16: =CONCATENATE(A16,"PROG") -> PROG | G16: =CONCATENATE("P",(LEFT(F16,3)),A16) -> P | J16: =CONCATENATE("ELEM",LEFT(I16,2)) -> ELEM | M16: #N/A
E17: =CONCATENATE(A17,"PROG") -> PROG | G17: =CONCATENATE("P",(LEFT(F17,3)),A17) -> P | J17: =CONCATENATE("ELEM",LEFT(I17,2)) -> ELEM | M17: #N/A
E18: =CONCATENATE(A18,"PROG") -> PROG | G18: =CONCATENATE("P",(LEFT(F18,3)),A18) -> P | J18: =CONCATENATE("ELEM",LEFT(I18,2)) -> ELEM | M18: #N/A
E19: =CONCATENATE(A19,"PROG") -> PROG | G19: =CONCATENATE("P",(LEFT(F19,3)),A19) -> P | J19: =CONCATENATE("ELEM",LEFT(I19,2)) -> ELEM | M19: #N/A
E20: =CONCATENATE(A20,"PROG") -> PROG | G20: =CONCATENATE("P",(LEFT(F20,3)),A20) -> P | J20: =CONCATENATE("ELEM",LEFT(I20,2)) -> ELEM | M20: #N/A
E21: =CONCATENATE(A21,"PROG") -> PROG | G21: =CONCATENATE("P",(LEFT(F21,3)),A21) -> P | J21: =CONCATENATE("ELEM",LEFT(I21,2)) -> ELEM | M21: #N/A
E22: =CONCATENATE(A22,"PROG") -> PROG | G22: =CONCATENATE("P",(LEFT(F22,3)),A22) -> P | J22: =CONCATENATE("ELEM",LEFT(I22,2)) -> ELEM | M22: #N/A
E23: =CONCATENATE(A23,"PROG") -> PROG | G23: =CONCATENATE("P",(LEFT(F23,3)),A23) -> P | J23: =CONCATENATE("ELEM",LEFT(I23,2)) -> ELEM | M23: #N/A
E24: =CONCATENATE(A24,"PROG") -> PROG | G24: =CONCATENATE("P",(LEFT(F24,3)),A24) -> P | J24: =CONCATENATE("ELEM",LEFT(I24,2)) -> ELEM | M24: #N/A
E25: =CONCATENATE(A25,"PROG") -> PROG | G25: =CONCATENATE("P",(LEFT(F25,3)),A25) -> P | J25: =CONCATENATE("ELEM",LEFT(I25,2)) -> ELEM | M25: #N/A
E26: =CONCATENATE(A26,"PROG") -> PROG | G26: =CONCATENATE("P",(LEFT(F26,3)),A26) -> P | J26: =CONCATENATE("ELEM",LEFT(I26,2)) -> ELEM | M26: #N/A
E27: =CONCATENATE(A27,"PROG") -> PROG | G27: =CONCATENATE("P",(LEFT(F27,3)),A27) -> P | J27: =CONCATENATE("ELEM",LEFT(I27,2)) -> ELEM | M27: #N/A
... E501: =CONCATENATE(A501,"PROG") -> PROG | G501: =CONCATENATE("P",(LEFT(F501,3)),A501) -> P | J501: =CONCATENATE("ELEM",LEFT(I501,2)) -> ELEM | M501: #N/A

Sheet EXEMPLO PREENCHIMENTO OBZ
A1: UNIDADE ORÇAMENTÁRIA (NÍVEL 1) | B1: SUBSECRETARIA (NÍVEL 2) | C1: SUB SIGLA | D1: SUPERINTENDENCIA (NÍVEL 3) | E1: PROGRAMAUO | F1: PROGRAMA | G1: prog cod | H1: AÇÃO | I1: ENTREGA | J1: ELEMENTO | K1: elem cod | L1: ELEMENTO_ITEM | M1: GRUPO | N1: FONTEUO | O1: FONTE (OPCIONAL) | P1: ITEM DE MATERIAL (OPCIONAL) | Q1: NOVO? | R1: PREMISSA VOLUME | S1: VOLUME | T1: PREMISSA DE PREÇO | U1: PREÇO UNITÁRIO | V1: FREQUÊNCIA PAGAMENTO | W1: VALOR TOTAL ITEM | X1: CLASSIFICAÇÃO CENÁRIO | Y1: DESCRIÇÃO DO CENÁRIO - pacotes de despesa / gera valor agregado | Z1: RISCO DE NÃO FAZER | AA1: BENEFICIO AO FAZER | AB1: PRIORIDADE N3 | AC1: PRIORIDADE N2 | AD1: PRIORIDADE N1
A2: FAOP | E2: =CONCATENATE(A2,"PROG") -> FAOPPROG | F2: 060 - FORMACAO CULTURAL | G2: =CONCATENATE("P",(LEFT(F2,3)),A2) -> P060FAOP | H2: 1029 - ATIVIDADES DE ENSINO, FORMACAO E QUALIFICACAO PROFISSIONAL E TECNICA EM CULTURA E PATRIMONIO | I2: CURSO DE CAPACITAÇÃO | J2: 30 - MATERIAL DE CONSUMO | K2: =CONCATENATE("ELEM",LEFT(J2,2)) -> ELEM30 | L2: 3012 - MEDICAMENTOS | M2: 3 - Outras Despesas de Custeio | N2: =CONCATENATE("FONTE",A2) -> FONTEFAOP | O2: 45 | Q2: NÃO | R2: NÚMERO DE DIÁRIAS UTILIZADAS (2) X NUMERO DE SERVIDORES FAVORECIDOS (1) | S2: 2 | T2: VALOR DA DIÁRIA | U2: 200 | V2: 1 | W2: =S2*U2*V2 -> 400 | X2: LIMIAR | Y2: curso com um professor | Z2: curso precisa de pelo menos um professor | AA2: não tem como ter curso sem professor
A3: FAOP | E3: =CONCATENATE(A3,"PROG") -> FAOPPROG | F3: 060 - FORMACAO CULTURAL | G3: =CONCATENATE("P",(LEFT(F3,3)),A3) -> P060FAOP | H3: 1029 - ATIVIDADES DE ENSINO, FORMACAO E QUALIFICACAO PROFISSIONAL E TECNICA EM CULTURA E PATRIMONIO | I3: CURSO DE CAPACITAÇÃO | J3: 33 - PASSAGENS E DESPESAS COM LOCOMOÇÃO | K3: =CONCATENATE("ELEM",LEFT(J3,2)) -> ELEM33 | L3: 3301 - PASSAGENS - PESSOA FÍSICA | M3: 3 - Outras Despesas de Custeio | N3: =CONCATENATE("FONTE",A3) -> FONTEFAOP | O3: 45 | Q3: NÃO | R3: 1 PASSAGEM DE IDA E VOLTA DE OURO PRETO PARA BH | S3: 1 | T3: VALOR DA PASSAGEM IDA E VOLTA | U3: 45 | V3: 1 | W3: =S3*U3*V3 -> 45 | X3: LIMIAR | Y3: curso com um professor | Z3: curso precisa de pelo menos um professor | AA3: não tem como ter curso sem professor
A4: FAOP | E4: =CONCATENATE(A4,"PROG") -> FAOPPROG | F4: 060 - FORMACAO CULTURAL | G4: =CONCATENATE("P",(LEFT(F4,3)),A4) -> P060FAOP | H4: 1029 - ATIVIDADES DE ENSINO, FORMACAO E QUALIFICACAO PROFISSIONAL E TECNICA EM CULTURA E PATRIMONIO | I4: CURSO DE CAPACITAÇÃO | J4: 14 - DIÁRIAS - CIVIL | K4: =CONCATENATE("ELEM",LEFT(J4,2)) -> ELEM14 | L4: 1401 - DIÁRIAS CIVIL | M4: 3 - Outras Despesas de Custeio | N4: =CONCATENATE("FONTE",A4) -> FONTEFAOP | O4: 45 | Q4: NÃO | R4: NÚMERO DE DIÁRIAS UTILIZADAS (2) X NUMERO DE SERVIDORES FAVORECIDOS (1) | S4: 2 | T4: VALOR DA DIÁRIA | U4: 200 | V4: 1 | W4: =S4*U4*V4 -> 400 | X4: INCREMENTAL | Y4: curso com professor convidado | Z4: CURSO MENOS INTERESSANTE, MENOR CARGA HORÁRIO E POSSÍVEL MENOS ADESÃO DO PÚBLICO | AA4: 1 | AB4: 1
A5: FAOP | E5: =CONCATENATE(A5,"PROG") -> FAOPPROG | F5: 060 - FORMACAO CULTURAL | G5: =CONCATENATE("P",(LEFT(F5,3)),A5) -> P060FAOP | H5: 1029 - ATIVIDADES DE ENSINO, FORMACAO E QUALIFICACAO PROFISSIONAL E TECNICA EM CULTURA E PATRIMONIO | I5: CURSO DE CAPACITAÇÃO EM RESTAURAÇÃO | J5: 33 - PASSAGENS E DESPESAS COM LOCOMOÇÃO | K5: =CONCATENATE("ELEM",LEFT(J5,2)) -> ELEM33 | L5: 3301 - PASSAGENS - PESSOA FÍSICA | M5: 3 - Outras Despesas de Custeio | N5: =CONCATENATE("FONTE",A5) -> FONTEFAOP | O5: 45 | Q5: NÃO | R5: 1 PASSAGEM DE IDA E VOLTA DE OURO PRETO PARA BH | S5: 1 | T5: VALOR DA PASSAGEM IDA E VOLTA | U5: 45 | V5: 1 | W5: =S5*U5*V5 -> 45 | X5: INCREMENTAL | Y5: curso com professor convidado | Z5: CURSO MENOS INTERESSANTE, MENOR CARGA HORÁRIO E POSSÍVEL MENOS ADESÃO DO PÚBLICO | AA5: CURSO COM MAIOR QUALIDADE E ADESÃO DO PÚBLICO | AB5: 1
A6: FAOP | E6: =CONCATENATE(A6,"PROG") -> FAOPPROG | F6: 060 - FORMACAO CULTURAL | G6: =CONCATENATE("P",(LEFT(F6,3)),A6) -> P060FAOP | H6: 1029 - ATIVIDADES DE ENSINO, FORMACAO E QUALIFICACAO PROFISSIONAL E TECNICA EM CULTURA E PATRIMONIO | I6: CURSO DE CAPACITAÇÃO EM RESTAURAÇÃO | J6: 30 - MATERIAL DE CONSUMO | K6: =CONCATENATE("ELEM",LEFT(J6,2)) -> ELEM30 | L6: 3004 - MATERIAL GRÁFICO E IMPRESSOS | M6: 3 - Outras Despesas de Custeio | N6: =CONCATENATE("FONTE",A6) -> FONTEFAOP | O6: 45 | P6: IMPRESSÃO DE FLYER PARA DIVULGAÇÃO (TAMANHO MEIO OFÍCIO) | Q6: NÃO | R6: QUANTITATIVO DE FLYERS NECESSÁRIOS PARA DIVULGAÇÃO DO EVENTO | S6: 300 | T6: PESQUISA DE PREÇO NA INTERNET | U6: 0.3 | V6: 1 | W6: =S6*U6*V6 -> 90 | X6: INCREMENTAL | Y6: curso com um professor | Z6: POUCAS INSCRIÇÕES NO CURSO DEVIDO A FALTA DE DIVULGAÇÃO - TER QUE DIVULGAR SOMENTE PELA INTERNET | AA6: MAIS PESSOAS CONHECENDO O CURSO E MAIORES CHANCES DE INSCRIÇÕES | AB6: 1
A7: FAOP | E7: =CONCATENATE(A7,"PROG") -> FAOPPROG | F7: 060 - FORMACAO CULTURAL | G7: =CONCATENATE("P",(LEFT(F7,3)),A7) -> P060FAOP | H7: 1029 - ATIVIDADES DE ENSINO, FORMACAO E QUALIFICACAO PROFISSIONAL E TECNICA EM CULTURA E PATRIMONIO | I7: CURSO DE CAPACITAÇÃO EM RESTAURAÇÃO | J7: 30 - MATERIAL DE CONSUMO | K7: =CONCATENATE("ELEM",LEFT(J7,2)) -> ELEM30 | L7: 3004 - MATERIAL GRÁFICO E IMPRESSOS | M7: 3 - Outras Despesas de Custeio | N7: =CONCATENATE("FONTE",A7) -> FONTEFAOP | O7: 45 | P7: IMPRESSÃO DE FLYER PARA DIVULGAÇÃO (TAMANHO MEIO OFÍCIO) | Q7: SIM | R7: QUANTITATIVO DE FLYERS NECESSÁRIOS PARA DIVULGAÇÃO DO EVENTO | S7: 200 | T7: PESQUISA DE PREÇO NA INTERNET | U7: 0.3 | V7: 1 | W7: =S7*U7*V7 -> 60 | X7: INCREMENTAL | Y7: curso com um professor e professor convidado | Z7: POUCAS INSCRIÇÕES NO CURSO DEVIDO A FALTA DE DIVULGAÇÃO | AA7: MAIS PESSOAS CONHECENDO O CURSO E MAIORES CHANCES DE INSCRIÇÕES | AB7: 2
A8: FAOP | E8: =CONCATENATE(A8,"PROG") -> FAOPPROG | F8: 060 - FORMACAO CULTURAL | G8: =CONCATENATE("P",(LEFT(F8,3)),A8) -> P060FAOP | H8: 1029 - ATIVIDADES DE ENSINO, FORMACAO E QUALIFICACAO PROFISSIONAL E TECNICA EM CULTURA E PATRIMONIO | I8: CURSO DE CAPACITAÇÃO EM RESTAURAÇÃO | J8: 30 - MATERIAL DE CONSUMO | K8: =CONCATENATE("ELEM",LEFT(J8,2)) -> ELEM30 | L8: 3005 - MATERIAL PARA ESCRITÓRIO | M8: 3 - Outras Despesas de Custeio | N8: =CONCATENATE("FONTE",A8) -> FONTEFAOP | O8: 45 | P8: PACOTE DEFOLHA A4 BRANCA COM 100 UNIDADES | Q8: NÃO | R8: MÉDIA DE CONSUMO PARA UM CURSO DE 2 DIAS | S8: 1 | T8: CONSULTA DO VALOR DO ITEM NO SIAD | U8: 25 | V8: 1 | W8: =S8*U8*V8 -> 25 | X8: LIMIAR | Y8: curso com um professor e professor convidado
A9: FAOP | E9: =CONCATENATE(A9,"PROG") -> FAOPPROG | F9: 060 - FORMACAO CULTURAL | G9: =CONCATENATE("P",(LEFT(F9,3)),A9) -> P060FAOP | H9: 1029 - ATIVIDADES DE ENSINO, FORMACAO E QUALIFICACAO PROFISSIONAL E TECNICA EM CULTURA E PATRIMONIO | I9: CURSO DE CAPACITAÇÃO EM RESTAURAÇÃO | J9: 30 - MATERIAL DE CONSUMO | K9: =CONCATENATE("ELEM",LEFT(J9,2)) -> ELEM30 | L9: 3005 - MATERIAL PARA ESCRITÓRIO | M9: 3 - Outras Despesas de Custeio | N9: =CONCATENATE("FONTE",A9) -> FONTEFAOP | O9: 45 | P9: PACOTE DEFOLHA A4 BRANCA COM 100 UNIDADES | Q9: NÃO | R9: MÉDIA DE CONSUMO PARA UM CURSO DE 2 DIAS | S9: 1 | T9: CONSULTA DO VALOR DO ITEM NO SIAD | U9: 25 | V9: 1 | W9: =S9*U9*V9 -> 25 | X9: LIMIAR | Y9: curso com um professor
X10: INCREMENTAL | Y10: curso com coffe break
X11: INCREMENTAL | Y11: curso com coffe break
A12: FAOP | E12: =CONCATENATE(A12,"PROG") -> FAOPPROG | F12: 060 - FORMACAO CULTURAL | G12: =CONCATENATE("P",(LEFT(F12,3)),A12) -> P060FAOP | H12: 1029 - ATIVIDADES DE ENSINO, FORMACAO E QUALIFICACAO PROFISSIONAL E TECNICA EM CULTURA E PATRIMONIO | I12: MANUTENÇÃO DO ESPAÇO DE REALIZAÇÃO DOS CURSOS | J12: 37 - LOCAÇÃO DE MÃO-DE-OBRA | K12: =CONCATENATE("ELEM",LEFT(J12,2)) -> ELEM37 | L12: 3703 - LOCAÇÃO DE SERVIÇOS DE CONSERVAÇÃO E LIMPEZA REALIZADOS PELA MGS | M12: 3 - Outras Despesas de Custeio | N12: =CONCATENATE("FONTE",A12) -> FONTEFAOP | Q12: NÃO | R12: NÚMERO DE VIGIAS NECESSÁRIOS PARA SEGURANÇA MEIO TURNO | S12: 2 | T12: VALOR MENSAL DO POSTO DE TRABALHO CONFORME CONTRATO | U12: 2000 | V12: 12 | W12: =S12*U12*V12 -> 48000 | X12: LIMIAR
A13: FAOP | E13: =CONCATENATE(A13,"PROG") -> FAOPPROG | F13: 060 - FORMACAO CULTURAL | G13: =CONCATENATE("P",(LEFT(F13,3)),A13) -> P060FAOP | H13: 1029 - ATIVIDADES DE ENSINO, FORMACAO E QUALIFICACAO PROFISSIONAL E TECNICA EM CULTURA E PATRIMONIO | I13: MANUTENÇÃO DO ESPAÇO DE REALIZAÇÃO DOS CURSOS | J13: 37 - LOCAÇÃO DE MÃO-DE-OBRA | K13: =CONCATENATE("ELEM",LEFT(J13,2)) -> ELEM37 | L13: 3703 - LOCAÇÃO DE SERVIÇOS DE CONSERVAÇÃO E LIMPEZA REALIZADOS PELA MGS | M13: 3 - Outras Despesas de Custeio | N13: =CONCATENATE("FONTE",A13) -> FONTEFAOP | Q13: SIM | R13: NÚMERO DE VIGIAS NECESSÁRIOS PARA SEGURANÇA 24 HORAS | S13: 2 | T13: VALOR MENSAL DO POSTO DE TRABALHO CONFORME CONTRATO | U13: 2000 | V13: 12 | W13: =S13*U13*V13 -> 48000 | X13: INCREMENTAL
A14: FAOP | E14: =CONCATENATE(A14,"PROG") -> FAOPPROG | F14: 060 - FORMACAO CULTURAL | G14: =CONCATENATE("P",(LEFT(F14,3)),A14) -> P060FAOP | H14: 1029 - ATIVIDADES DE ENSINO, FORMACAO E QUALIFICACAO PROFISSIONAL E TECNICA EM CULTURA E PATRIMONIO | I14: MANUTENÇÃO DO ESPAÇO DE REALIZAÇÃO DOS CURSOS | J14: 37 - LOCAÇÃO DE MÃO-DE-OBRA | K14: =CONCATENATE("ELEM",LEFT(J14,2)) -> ELEM37 | L14: 3703 - LOCAÇÃO DE SERVIÇOS DE CONSERVAÇÃO E LIMPEZA REALIZADOS PELA MGS | M14: 3 - Outras Despesas de Custeio | N14: =CONCATENATE("FONTE",A14) -> FONTEFAOP | Q14: NÃO | R14: NÚMERO DE FAXINEIRAS PARA MANUTENÇÃO DO ESPAÇO DOS CURSOS | S14: 1 | T14: VALOR MENSAL DO POSTO DE TRABALHO CONFORME CONTRATO | U14: 1500 | V14: 12 | W14: =S14*U14*V14 -> 18000 | X14: LIMIAR | Y14: segurança 24 horas | AB14: 1
A15: FAOP | E15: =CONCATENATE(A15,"PROG") -> FAOPPROG | F15: 060 - FORMACAO CULTURAL | G15: =CONCATENATE("P",(LEFT(F15,3)),A15) -> P060FAOP | H15: 1029 - ATIVIDADES DE ENSINO, FORMACAO E QUALIFICACAO PROFISSIONAL E TECNICA EM CULTURA E PATRIMONIO | I15: MANUTENÇÃO DO ESPAÇO DE REALIZAÇÃO DOS CURSOS | J15: 39 - OUTROS SERVIÇOS DE TERCEIROS - PESSOA JURÍDICA | K15: =CONCATENATE("ELEM",LEFT(J15,2)) -> ELEM39 | L15: 3912 - TARIFA DE ENERGIA ELÉTRICA | M15: 3 - Outras Despesas de Custeio | N15: =CONCATENATE("FONTE",A15) -> FONTEFAOP | Q15: NÃO | R15: fazer o rateio | S15: 1 | T15: VALOR MENSAL DO POSTO DE TRABALHO CONFORME CONTRATO | U15: 1500 | V15: 12 | W15: =S15*U15*V15 -> 18000 | X15: LIMIAR
J16: 39 - OUTROS SERVIÇOS DE TERCEIROS - PESSOA JURÍDICA
A18: DER | E18: =CONCATENATE(A18,"PROG") -> DERPROG | F18: 081 - INFRAESTRUTURA RODOVIARIA | G18: =CONCATENATE("P",(LEFT(F18,3)),A18) -> P081DER | H18: 2039 - RECUPERACAO E MANUTENCAO DA MALHA VIARIA | I18: RECAPEAMENTO DE VIAS | J18: 51 - OBRAS E INSTALAÇÕES | K18: =CONCATENATE("ELEM",LEFT(J18,2)) -> ELEM51 | L18: 5107 - EXECUÇÃO DE OBRAS POR CONTRATO DE BENS NÃO PATRIMONIÁVEIS | M18: 4 - Investimento | N18: =CONCATENATE("FONTE",A18) -> FONTEDER | Q18: NÃO | R18: KM DE RODOVIA A SEREM PAVIMENTADOS | S18: 500 | T18: VALOR MÉDIO POR KM PAVIMENTADO | U18: 50000 | V18: 1 | W18: =S18*U18*V18 -> 25000000
A19: DER | E19: =CONCATENATE(A19,"PROG") -> DERPROG | F19: 081 - INFRAESTRUTURA RODOVIARIA | G19: =CONCATENATE("P",(LEFT(F19,3)),A19) -> P081DER | H19: 2039 - RECUPERACAO E MANUTENCAO DA MALHA VIARIA | I19: RECAPEAMENTO DE VIAS | J19: 35 - SERVIÇOS DE CONSULTORIA | K19: =CONCATENATE("ELEM",LEFT(J19,2)) -> ELEM35 | L19: 3502 - SERVIÇOS DE CONSULTORIA ? PESSOA JURÍDICA | M19: 3 - Outras Despesas de Custeio | N19: =CONCATENATE("FONTE",A19) -> FONTEDER | P19: CONTRATAÇÃO DE CONSULTORIA PARA REALIZAÇÃO DE PROJETO DE ENGENHARIA | Q19: SIM | R19: CONTRATO FIRMADO | S19: 1 | T19: VALOR MÉDIO DE MERCADO | U19: 25000 | V19: 1 | W19: =S19*U19*V19 -> 25000
E20: =CONCATENATE(A20,"PROG") -> PROG | G20: =CONCATENATE("P",(LEFT(F20,3)),A20) -> P | K20: =CONCATENATE("ELEM",LEFT(J20,2)) -> ELEM | N20: =CONCATENATE("FONTE",A20) -> FONTE | W20: =S20*U20*V20 -> 0
E21: =CONCATENATE(A21,"PROG") -> PROG | G21: =CONCATENATE("P",(LEFT(F21,3)),A21) -> P | K21: =CONCATENATE("ELEM",LEFT(J21,2)) -> ELEM | N21: =CONCATENATE("FONTE",A21) -> FONTE | W21: =S21*U21*V21 -> 0
E22: =CONCATENATE(A22,"PROG") -> PROG | G22: =CONCATENATE("P",(LEFT(F22,3)),A22) -> P | K22: =CONCATENATE("ELEM",LEFT(J22,2)) -> ELEM | N22: =CONCATENATE("FONTE",A22) -> FONTE | W22: =S22*U22*V22 -> 0
E23: =CONCATENATE(A23,"PROG") -> PROG | G23: =CONCATENATE("P",(LEFT(F23,3)),A23) -> P | K23: =CONCATENATE("ELEM",LEFT(J23,2)) -> ELEM | N23: =CONCATENATE("FONTE",A23) -> FONTE | W23: =S23*U23*V23 -> 0
E24: =CONCATENATE(A24,"PROG") -> PROG | G24: =CONCATENATE("P",(LEFT(F24,3)),A24) -> P | K24: =CONCATENATE("ELEM",LEFT(J24,2)) -> ELEM | N24: =CONCATENATE("FONTE",A24) -> FONTE | W24: =S24*U24*V24 -> 0
E25: =CONCATENATE(A25,"PROG") -> PROG | G25: =CONCATENATE("P",(LEFT(F25,3)),A25) -> P | K25: =CONCATENATE("ELEM",LEFT(J25,2)) -> ELEM | N25: =CONCATENATE("FONTE",A25) -> FONTE | W25: =S25*U25*V25 -> 0
E26: =CONCATENATE(A26,"PROG") -> PROG | G26: =CONCATENATE("P",(LEFT(F26,3)),A26) -> P | K26: =CONCATENATE("ELEM",LEFT(J26,2)) -> ELEM | N26: =CONCATENATE("FONTE",A26) -> FONTE | W26: =S26*U26*V26 -> 0
E27: =CONCATENATE(A27,"PROG") -> PROG | G27: =CONCATENATE("P",(LEFT(F27,3)),A27) -> P | K27: =CONCATENATE("ELEM",LEFT(J27,2)) -> ELEM | N27: =CONCATENATE("FONTE",A27) -> FONTE | W27: =S27*U27*V27 -> 0
E28: =CONCATENATE(A28,"PROG") -> PROG | G28: =CONCATENATE("P",(LEFT(F28,3)),A28) -> P | K28: =CONCATENATE("ELEM",LEFT(J28,2)) -> ELEM | N28: =CONCATENATE("FONTE",A28) -> FONTE | W28: =S28*U28*V28 -> 0
E29: =CONCATENATE(A29,"PROG") -> PROG | G29: =CONCATENATE("P",(LEFT(F29,3)),A29) -> P | K29: =CONCATENATE("ELEM",LEFT(J29,2)) -> ELEM | N29: =CONCATENATE("FONTE",A29) -> FONTE | W29: =S29*U29*V29 -> 0
E30: =CONCATENATE(A30,"PROG") -> PROG | G30: =CONCATENATE("P",(LEFT(F30,3)),A30) -> P | K30: =CONCATENATE("ELEM",LEFT(J30,2)) -> ELEM | N30: =CONCATENATE("FONTE",A30) -> FONTE | W30: =S30*U30*V30 -> 0
E31: =CONCATENATE(A31,"PROG") -> PROG | G31: =CONCATENATE("P",(LEFT(F31,3)),A31) -> P | K31: =CONCATENATE("ELEM",LEFT(J31,2)) -> ELEM | N31: =CONCATENATE("FONTE",A31) -> FONTE | W31: =S31*U31*V31 -> 0
... E215: =CONCATENATE(A215,"PROG") -> PROG | G215: =CONCATENATE("P",(LEFT(F215,3)),A215) -> P | K215: =CONCATENATE("ELEM",LEFT(J215,2)) -> ELEM | N215: =CONCATENATE("FONTE",A215) -> FONTE | W215: =S215*U215*V215 -> 0

Sheet PONTOS IMPORTANTES
H1: INDICE
B2: PONTOS IMPORTANTES NA ELABORAÇÃO DO OBZ
B4: Cenário Limiar: nível de serviço mínimo aceitável para garantir a execução de entregas (políticas públicas) essenciais às condições de sobrevivência do órgão | E4: Cenário Incremental: despesas que geram nível de serviço e de qualidade superiores, realizadas para melhorar os resultados ou diminuir riscos. (Por exemplo: cenários intermediários e ótimo).
B6: O OBZ terá como foco a margem discricionária do orçamento de cada órgão: despesas de custeio e capital sobre as quais a unidade tem liberdade de alocação. As Planilhas OBZ não conterão, portanto: Despesas com pessoal (Grupo 1) e auxílios (IPU 7); Fontes de recursos vinculadas a instrumentos jurídicos (exemplos: convênios e contrapartidas, fontes federais, recursos da Vale, etc.); Emendas parlamentares e de CPP (IPUs 8 e 4); Despesas com precatórios (IPU 9); Despesas de Recursos Recebidos para Contrapartida (IPU 3 e 6) e Despesas de Exercícios Anteriores (DEA - Elemento de despesa 92)
B8: PONTOS DE ATENÇÃO – PREENCHIMENTO DA PLANILHA
B10: Preencher riscos de não fazer e benefícios de fazer para: Cenários Limiar e Incremental | E10: Não existe prioridade entre cenários limiares de diferentes níveis N3. Todo cenário limiar será prioridade 0 (zero).
B12: Se atentar ao número de cenários por ação, com intuito de viabilizar análise gerencial: o nível N1 analisará toda a planilha, portanto é necessário que a forma de construção dos cenários permita uma visão consolidada dos dados, e apresente um valor significante em relação ao orçamento do órgão.

Sheet ELEMENTO
A1: 13 - OBRIGAÇÕES PATRONAIS | B1: 14 - DIÁRIAS - CIVIL | C1: 15 - DIÁRIAS - MILITAR | D1: 16 - OUTRAS DESPESAS VARIÁVEIS - PESSOAL CIVIL | E1: 17 - OUTRAS DESPESAS VARIÁVEIS - PESSOAL MILITAR | F1: 18 - AUXÍLIO FINANCEIRO A ESTUDANTES | G1: 19 - AUXÍLIO-FARDAMENTO | H1: 20 - AUXÍLIO FINANCEIRO A PESQUISADORES | I1: 30 - MATERIAL DE CONSUMO | J1: 31 - PREMIAÇÕES CULTURAIS, ARTÍSTICAS, CIENTÍFICAS, DESPORTIVAS E OUTRAS. | K1: 32 - MATERIAL, BEM OU SERVIÇO PARA DISTRIBUIÇÃO GRATUITA | L1: 33 - PASSAGENS E DESPESAS COM LOCOMOÇÃO | M1: 34 - OUTRAS DESPESAS DE PESSOAL DECORRENTES DE CONTRATOS DE TERCEIRIZAÇÃO | N1: 35 - SERVIÇOS DE CONSULTORIA | O1: 36 - OUTROS SERVIÇOS DE TERCEIROS - PESSOA FÍSICA | P1: 37 - LOCAÇÃO DE MÃO-DE-OBRA | Q1: 38 - ARRENDAMENTO MERCANTIL | R1: 39 - OUTROS SERVIÇOS DE TERCEIROS - PESSOA JURÍDICA | S1: 40 - SERVIÇOS DE TECNOLOGIA DA INFORMAÇÃO E COMUNICAÇÃO - PESSOA JURÍDICA | T1: 41 - CONTRIBUIÇÕES | U1: 42 - AUXÍLIOS | V1: 43 - SUBVENÇÕES SOCIAIS | W1: 45 - SUBVENÇÕES ECONÔMICAS | X1: 47 - OBRIGAÇÕES TRIBUTÁRIAS E CONTRIBUTIVAS | Y1: 48 - OUTROS AUXÍLIOS FINANCEIROS A PESSOAS FÍSICAS | Z1: 51 - OBRAS E INSTALAÇÕES | AA1: 52 - EQUIPAMENTOS E MATERIAL PERMANENTE | AB1: 61 - AQUISIÇÃO DE IMÓVEIS | AC1: 62 - AQUISIÇÃO DE PRODUTOS PARA REVENDA | AD1: 63 - AQUISIÇÃO DE TÍTULOS DE CRÉDITO | AE1: 64 - AQUISIÇÃO DE TÍTULOS REPRESENTATIVOS DE CAPITAL JÁ INTEGRALIZADO | AF1: 65 - CONSTITUIÇÃO OU AUMENTO DE CAPITAL DE EMPRESAS | AG1: 66 - CONCESSÃO DE EMPRÉSTIMOS E FINANCIAMENTOS | AH1: 67 - DEPÓSITOS COMPULSÓRIOS | AI1: 93 - INDENIZAÇÕES E RESTITUIÇÕES | AJ1: 94 - INDENIZAÇÕES E RESTITUIÇÕES TRABALHISTAS | AK1: 95 - INDENIZAÇÃO PELA EXECUÇÃO DE TRABALHOS DE CAMPO
A2: 1304 - INSS | B2: 1401 - DIÁRIAS CIVIL | C2: 1501 - DIÁRIAS MILITAR | D2: 1601 - SERVIÇO EXTRAORDINÁRIO | E2: 1701 - OUTRAS DESPESAS VARIÁVEIS ? PESSOAL MILITAR | F2: 1801 - AUXÍLIO FINANCEIRO A ESTUDANTES | G2: 1901 - AUXÍLIO-FARDAMENTO | H2: 2001 - AUXÍLIO FINANCEIRO A PESQUISADORES | I2: 3001 - ARTIGOS PARA CONFECÇÃO E VESTUÁRIO | J2: 3101 - PRÊMIOS, DIPLOMAS, CONDECORAÇÕES E MEDALHAS | K2: 3201 - MATERIAL DE DISTRIBUIÇÃO GRATUITA | L2: 3301 - PASSAGENS - PESSOA FÍSICA | M2: 3401 - OUTRAS DESPESAS DE PESSOAL DECORRENTES DE CONTRATOS DE TERCEIRIZAÇÃO | N2: 3501 - SERVIÇOS DE CONSULTORIA ? PESSOA FÍSICA | O2: 3601 - ESTAGIÁRIOS | P2: 3701 - LOCAÇÃO DE SERVIÇOS DE CONSERVAÇÃO E LIMPEZA | Q2: 3801 - ARRENDAMENTO MERCANTIL | R2: 3901 - VALE-TRANSPORTE | S2: 4002 - SERVIÇOS DE TECNOLOGIA DA INFORMAÇÃO | T2: 4101 - CONTRIBUIÇÕES | U2: 4201 - AUXÍLIOS | V2: 4301 - SUBVENÇÕES SOCIAIS | W2: 4501 - SUBVENÇÕES ECONÔMICAS | X2: 4702 - IMPOSTO DE RENDA - IR | Y2: 4801 - OUTROS AUXÍLIOS FINANCEIROS A PESSOAS FÍSICAS | Z2: 5101 - ESTUDOS E PROJETOS DE BENS PATRIMONIÁVEIS | AA2: 5201 - AERONAVES E COMPONENTES ESTRUTURAIS | AB2: 6101 - TERRENOS | AC2: 6201 - AQUISIÇÃO DE PRODUTOS PARA REVENDA | AD2: 6301 - AQUISIÇÃO DE TÍTULOS DE CRÉDITO | AE2: 6401 - AQUISIÇÃO DE TÍTULOS REPRESENTATIVOS DE CAPITAL JÁ INTEGRALIZADO | AF2: 6501 - CONSTITUIÇÃO OU AUMENTO DE CAPITAL DE EMPRESAS | AG2: 6601 - CONCESSÃO DE EMPRÉSTIMOS E FINANCIAMENTOS | AH2: 6701 - DEPÓSITOS COMPULSÓRIOS | AI2: 9301 - AJUDA DE CUSTO | AJ2: 9401 - INDENIZAÇÕES E RESTITUIÇÕES TRABALHISTAS | AK2: 9501 - INDENIZAÇÃO PELA EXECUÇÃO DE TRABALHOS DE CAMPO
A3: 1305 - OBRIGAÇÃO PATRONAL - PESSOAL ATIVO - PREVIDÊNCIA | D3: 1602 - SUBSTITUIÇÃO EM CARGOS EM COMISSÃO | G3: 1902 - ADIANTAMENTO ? FARDAMENTO | I3: 3002 - ARTIGOS PARA ESPORTE | J3: 3102 - PRÊMIOS LOTÉRICOS | K3: 3202 - MATERIAL DE ASSISTÊNCIA HUMANITÁRIA | L3: 3302 - DESPESAS COM TRANSPORTE URBANO, PEDÁGIO E ESTACIONAMENTO - PESSOA FÍSICA | M3: 3402 - AGENTES PENITENCIÁRIOS | N3: 3502 - SERVIÇOS DE CONSULTORIA ? PESSOA JURÍDICA | O3: 3602 - MÉDICOS RESIDENTES | P3: 3702 - LOCAÇÃO DE SERVIÇOS DE APOIO ADMINISTRATIVO | R3: 3902 - VALE-REFEIÇÃO | S3: 4003 - SERVIÇOS DE INFORMÁTICA EXECUTADOS PELA PRODEMGE | T3: 4102 - TRANSFERÊNCIAS AO FUNDHAB | X3: 4703 - IMPOSTO PREDIAL TERRITORIAL URBANO - IPTU | Y3: 4802 - AUXILIO FINANCEIRO ? PROGRAMA POUPANÇA JOVEM | Z3: 5102 - EXECUÇÃO DIRETA DE OBRAS DE BENS PATRIMONIÁVEIS | AA3: 5202 - ANIMAIS DE TRABALHO, PRODUÇÃO E / OU REPRODUÇÃO | AB3: 6102 - SALAS E ESCRITÓRIOS | AF3: 6502 - CONSTITUIÇÃO OU AUMENTO DE CAPITAL DE EMPRESAS ? CAPITAL INTEGRALIZADO | AG3: 6602 - EMPRÉSTIMOS E FINANCIAMENTOS ? FUNDOS DE DESENVOLVIMENTO | AI3: 9302 - AJUDA DE CUSTO ESPECIAL | AJ3: 9330 - REEMBOLSO DE DESPESA REALIZADA E CONTRATOS OU CONVÊNIOS FIRMADOS EM REGIME DE PARCERIA
A4: 1306 - OBRIGAÇÃO PATRONAL - PESSOAL INATIVO - PREVIDÊNCIA | D4: 1603 - AULAS FACULTATIVAS | G4: 1903 - AUXILIO FARDAMENTO PAGO A PESSOAL CONTRATADO | I4: 303 - UTENSÍLIOS PARA COPA, REFEITÓRIO E COZINHA | J4: 3103 - COMISSÕES LOTÉRICAS | L4: 3303 - FRETAMENTO E LOCAÇÃO - PESSOA FÍSICA | M4: 3403 - OBRIGAÇÃO PATRONAL – INSS | N4: 3503 - SERVIÇOS DE CONSULTORIA ? ORGANISMO INTERNACIONAL | O4: 3603 - SALÁRIOS DE INTERNOS | P4: 3703 - LOCAÇÃO DE SERVIÇOS DE CONSERVAÇÃO E LIMPEZA REALIZADOS PELA MGS | R4: 3903 - FORNECIMENTO DE ALIMENTAÇÃO | S4: 4004 - SERVIÇO DE TELECOMUNICAÇÃO | T4: 4103 - CONTRIBUIÇÕES AO IPLEMG | X4: 4704 - IMPOSTO SOBRE OPERAÇÕES FINANCEIRAS - IOF | Y4: 4803 - AUXÍLIO PARA PROFISSIONAIS DE PROGRAMAS DE CAPACITAÇÃO E FORMAÇÃO | Z4: 5103 - EXECUÇÃO DE OBRAS POR CONTRATO DE BENS PATRIMONIÁVEIS | AA4: 5203 - ARMAMENTO E EQUIPAMENTO DE USO POLICIAL | AB4: 6103 - FAZENDAS | AG4: 6603 - CONCESSÃO DE FINANCIAMENTOS HABITACIONAIS | AI4: 9303 - PERDAS DECORRENTES DE APLICAÇÕES FINANCEIRAS
A5: 1308 - OBRIGAÇÃO PATRONAL - PENSIONISTAS - PREVIDÊNCIA | D5: 1604 - GRATIFICAÇÃO POR ENCARGOS EXTRAORDINÁRIOS | I5: 3004 - MATERIAL GRÁFICO E IMPRESSOS | J5: 3104 - PREMIAÇÕES | L5: 3304 - PASSAGENS - PESSOA JURÍDICA | M5: 3404 - OBRIGAÇÃO PATRONAL – ASSISTÊNCIA À SAÚDE | O5: 3604 - DIÁRIAS A COLABORADORES EVENTUAIS | P5: 3704 - LOCAÇÃO DE SERVIÇOS DE APOIO ADMINISTRATIVO REALIZADOS PELA MGS | R5: 3904 - CONFECÇÃO EM GERAL | S5: 4005 - REDE IP MULTISSERVIÇOS | T5: 4104 - CONTRIBUIÇÕES DO FUNDO ESTADUAL DE SAUDE - FES - LC 141/2012 | X5: 4705 - IMPOSTO SOBRE A PROPRIEDADE DE VEÍCULOS AUTOMOTORES - IPVA | Z5: 5104 - INSTALAÇÕES PARA OBRAS EM ANDAMENTO | AA5: 5204 - MÁQUINAS, APARELHOS, UTENSÍLIOS E EQUIPAMENTOS DE USO INDUSTRIAL | AB5: 6104 - EDIFÍCIOS | AI5: 9304 - DESPESAS REFERENTES A RESSARCIMENTO PREVISTO NO PROGRAMA PRIMEIRO EMPREGO DO ESTADO DE MINA GERAIS
A6: 1309 - OBRIGAÇÃO PATRONAL - PRECATÓRIOS - PREVIDÊNCIA | D6: 1605 - FÉRIAS-PRÊMIO | I6: 3005 - MATERIAL PARA ESCRITÓRIO | L6: 3305 - SERVIÇOS DE TRANSPORTES DE PASSAGEIROS, FRETAMENTO E LOCAÇÃO - PESSOA JURÍDICA | M6: 3405 - SALÁRIO-FAMÍLIA | O6: 3606 - FORNECIMENTO DE ALIMENTAÇÃO | P6: 3705 - DESPESAS COM O PAGAMENTO DE ENCARGOS TRABALHISTAS À MGS | R6: 3905 - TRANSPORTE E ACONDICIONAMENTO DE ANIMAIS | S6: 4006 - AQUISIÇÃO DE SOFTWARE | T6: 4105 - CONTRIBUIÇÕES À FUNDAÇÃO DE PREVIDÊNCIA COMPLEMENTAR DO ESTADO DE MINAS GERAIS -PREVCOM?MG | X6: 4706 - CONTRIBUIÇÃO PARA A FORMAÇÃO DO PASEP/PIS | Z6: 5106 - ESTUDOS E PROJETOS DE BENS NÃO PATRIMONIÁVEIS | AA6: 5205 - EMBARCAÇÕES, PONTÕES, DIQUES, FLUTUANTES E COMPONENTES ESTRUTURAIS | AB6: 6105 - IMÓVEIS PARA FINS DE TRANSFERÊNCIA A TERCEIROS | AI6: 9305 - DESPESAS DECORRENTES DE CONTRATOS DE CONCESSÃO OU PERMISSÃO
A7: 1310 - OBRIGAÇÃO PATRONAL - OUTRAS SENTENÇAS JUDICIAIS - PREVIDÊNCIA | D7: 1606 - JORNADA COMPLEMENTAR DE TRABALHO | I7: 3006 - MATERIAL DE DESENHO | O7: 3607 - CONFECÇÃO EM GERAL | P7: 3706 - LOCAÇÃO DE SERVIÇOS DE SAÚDE | R7: 3906 - TRANSPORTE E ACONDICIONAMENTO DE MATERIAIS E EQUIPAMENTOS | S7: 4007 - AQUISIÇÃO DE SOFTWARE DESENVOLVIDOS PELA PRODEMGE | T7: 4106 - TRANSFERÊNCIAS PARA FINANCIAMENTO DO TRANSPORTE ESCOLAR | X7: 4707 - TAXA DE LIMPEZA PÚBLICA E COLETA DE RESÍDUOS | Z7: 5107 - EXECUÇÃO DE OBRAS POR CONTRATO DE BENS NÃO PATRIMONIÁVEIS | AA7: 5206 - EQUIPAMENTOS DE COMUNICAÇÃO E TELEFONIA | AB7: 6106 - IMÓVEIS NECESSÁRIOS À REALIZAÇÃO DE OBRAS DE BENS PATRIMONIAVEIS | AI7: 9306 - RESTITUIÇÃO DE RECURSOS DE CONVÊNIO E DE CONTRAPARTIDA
A8: 1314 - OBRIGAÇÃO PATRONAL - ENCARGOS POR PAGAMENTO EM ATRASO | I8: 3007 - MATERIAL DE ENSINO | O8: 3608 - MÉDICOS | P8: 3707 - DESPESAS COM O PAGAMENTO DE OBRIGAÇÕES TRABALHISTAS | R8: 3909 - PUBLICIDADE | T8: 4107 - TRANSFERÊNCIAS ENTRE FUNDOS ESTADUAIS | X8: 4708 - TAXA DE ILUMINAÇÃO PÚBLICA | Z8: 5109 - EXECUÇÃO DIRETA DE OBRAS DE BENS NÃO PATRIMONIÁVEIS | AA8: 5207 - EQUIPAMENTOS DE INFORMÁTICA | AB8: 6107 - IMÓVEIS NECESSÁRIOS À REALIZAÇÃO DE OBRAS DE BENS NÃO-PATRIMONIAVEIS | AI8: 9307 - RESSARCIMENTO REFERENTE A PESSOAL REQUISITADO DA ADMINISTRAÇÃO ESTADUAL
A9: 1315 - OBRIGAÇÃO PATRONAL - PRÊMIO DE PRODUTIVIDADE | I9: 3008 - PRODUTOS ALIMENTÍCIOS | O9: 3609 - DENTISTAS | R9: 3910 - PRÊMIOS DE SEGUROS | T9: 4108 - TRANSFERÊNCIAS ESPECIAIS A MUNICÍPIOS | X9: 4709 - TAXAS AMBIENTAIS | Z9: 5110 - MATERIAL PARA OBRAS - BENS PATRIMONIÁVEIS | AA9: 5208 - EQUIPAMENTOS DE SOM, VÍDEO, FOTOGRÁFICO E CINEMATOGRÁFICO | AB9: 6108 - CASAS | AI9: 9308 - DESPESAS DE CARÁTER INDENIZATÓRIO RELATIVAS AO MANDADO PARLAMENTAR
A10: 1317 - INSS – DEMAIS DESPESAS | I10: 3009 - FORRAGENS E OUTROS ALIMENTOS PARA ANIMAIS | O10: 3610 - EVENTUAL DE GABINETE | R10: 3911 - ASSINATURAS DE JORNAIS, REVISTAS E PERIÓDICOS | X10: 4710 - PASEP - ADESÃO AO PARCELAMENTO DECORRENTE DE LEI ESPECÍFICA | Z10: 5111 - CONTRUÇÃO DE UNIDADES HABITACIONAIS | AA10: 5209 - EQUIPAMENTOS HOSPITALARES, ODONTOLÓGICOS E DE LABORATÓRIO | AI10: 9309 - PREMIO DE PRODUTIVIDADE
A11: 1318 - OBRIGAÇÃO PATRONAL PESSOAL INATIVO – ENTIDADES CONVENIADAS – ASSISTÊNCIA À SAÚDE | I11: 3010 - MATERIAL MÉDICO E HOSPITALAR | O11: 3611 - LOCAÇÃO DE BENS IMÓVEIS | R11: 3912 - TARIFA DE ENERGIA ELÉTRICA | X11: 4799 - OUTROS - OBRIGAÇÕES TRIBUTÁRIAS E CONTRIBUTIVAS | Z11: 5112 - MATERIAL PARA OBRAS - BENS NÃO PATRIMONIÁVEIS | AA11: 5210 - FERRAMENTAS, EQUIPAMENTOS E INSTRUMENTOS PARA OFICINA, MEDIÇÃO E INSPEÇÃO | AI11: 9310 - RESTITUIÇÃO DE RECEITA - EXERCÍCIO ANTERIOR
A12: 1319 - OBRIGAÇÃO PATRONAL PESSOAL MILITAR INATIVO LC 125/2012 – PREVIDÊNCIA | I12: 3011 - MATERIAL ODONTOLÓGICO | O12: 3612 - DESPESAS MIÚDAS DE PRONTO PAGAMENTO | R12: 3913 - TARIFA DE ÁGUA E ESGOTO | Z12: 5113 - INSTALAÇÕES PARA INCORPORAÇÃO A BENS IMÓVEIS | AA12: 5211 - INSTRUMENTOS DE LABORATÓRIO, MÉDICOS E ODONTOLÓGICOS | AI12: 9311 - COMPENSAÇÃO FINANCEIRA DOS REGIMES DE PREVIDÊNCIA
A13: 1320 - OBRIGAÇÃO PATRONAL PESSOAL MILITAR ATIVO LC 125/2012 - PREVIDÊNCIA | I13: 3012 - MEDICAMENTOS | O13: 3613 - PESSOAL DE ENFERMAGEM | R13: 3914 - SERVIÇO DE TELEFONIA | Z13: 5114 - EXECUÇÃO DE OBRAS POR EMPRESAS CONTROLADAS | AA13: 5212 - MÁQUINAS, APARELHOS, UTENSÍLIOS E EQUIPAMENTOS DE USO ADMINISTRATIVO | AI13: 9312 - INDENIZAÇÃO POR UTILIZAÇÃO DE BENS DE TERCEIROS
A14: 1321 - OBRIGAÇÃO PATRONAL - PESSOAL ATIVO - ASSISTÊNCIA À SAÚDE | I14: 3013 - MATERIAIS DE LABORATÓRIO E PRODUTOS QUÍMICOS EM GERAL | O14: 3614 - MONITORES, FISCAIS E EXAMINADORES | R14: 3915 - SERVIÇO POSTAL-TELEGRÁFICO | AA14: 5213 - MATERIAL ESPORTIVO E RECREATIVO | AI14: 9313 - REEMBOLSO DE DESPESAS MÉDICO-HOSPITALARES
A15: 1322 - OBRIGAÇÃO PATRONAL - PESSOAL INATIVO - ASSISTÊNCIA À SAÚDE | I15: 3014 - MATERIAL RADIOLÓGICO | O15: 3615 - ENCARGOS FINANCEIROS | R15: 3916 - LOCAÇÃO DE TV POR ASSINATURA | AA15: 5214 - MOBILIÁRIO | AI15: 9314 - INDENIZAÇÕES DETERMINADAS POR DECISÕES JUDICIAIS
A16: 1324 - OBRIGAÇÃO PATRONAL - PENSIONISTAS - ASSISTÊNCIA À SAÚDE | I16: 3015 - MATERIAL FOTOGRÁFICO, CINEMATOGRÁFICO E DE COMUNICAÇÃO | O16: 3616 - REPARO E MANUTENÇÃO DE VEÍCULOS | R16: 3917 - LOCAÇÃO DE VEÍCULOS | AA16: 5215 - OBJETOS DE ARTE E ANTIGÜIDADES | AI16: 9315 - INDENIZAÇÃO DECORRENTE DE RESCISÃO UNILATERAL
A17: 1325 - OBRIGAÇÃO PATRONAL - ADESÃO AO PARCELAMENTO DECORRENTE DE LEI ESPECÍFICA - PREVIDÊNCIA | I17: 3016 - MATERIAL DE INFORMÁTICA | O17: 3617 - REPAROS DE EQUIPAMENTOS, INSTALAÇÕES E MATERIAL PERMANENTE | R17: 3918 - REPAROS DE VEÍCULOS | AA17: 5216 - TRATORES, SIMILARES E IMPLEMENTOS | AI17: 9316 - INDENIZAÇÕES DETERMINADAS POR LEI ESPECÍFICA
A18: 1326 - OBRIGAÇÃO PATRONAL SUPLEMENTAR – PESSOAL ATIVO | I18: 3017 - ARTIGOS PARA LIMPEZA E HIGIENE | O18: 3618 - REPAROS DE BENS IMÓVEIS | R18: 3919 - LOCAÇÃO DE MÁQUINAS E EQUIPAMENTOS | AA18: 5217 - VEÍCULOS | AI18: 9317 - INDENIZAÇÃO DECORRENTE DO EXERCÍCIO DO CARGO DE CONSELHEIRO-PRESIDENTE E PROCURADOR-GERAL JUNTO AO TRIBUNAL DE CONTAS
I19: 3018 - MATÉRIAS-PRIMAS E PRODUTOS PARA MANIPULAÇÃO E INDÚSTRIAS DE TRANSFORMAÇÃO | O19: 3619 - CONFERÊNCIAS E EXPOSIÇÕES | R19: 3920 - LOCAÇÃO DE BENS IMÓVEIS | AA19: 5218 - COLEÇÕES E MATERIAIS BIBLIOGRÁFICOS | AI19: 9318 - DESPESAS COM AUXILIO MORADIA DE CARÁTER INDENIZATÓRIO RELATIVAS AO MANDADO PARLAMENTAR
I20: 3019 - MATERIAL PARA MANUTENÇÃO E REPAROS DE IMÓVEIS DE PROPRIEDADE DA ADMINISTRAÇÃO PÚBLICA | O20: 3620 - JETONS A CONSELHEIROS | R20: 3921 - INSTALAÇÃO, REPARAÇÃO, ADAPTAÇÃO E CONSERVAÇÃO DE EQUIPAMENTO E MATERIAL PERMANENTE | AA20: 5219 - INSTRUMENTOS MUSICAIS E ARTÍSTICOS | AI20: 9319 - INDENIZAÇÕES DECORRENTES DA UTILIZAÇÃO DE LEITOS DE INSTITUIÇÕES DE SAÚDE PRIVADAS
I21: 3020 - MATERIAL ELÉTRICO E ELETRÔNICO | O21: 3621 - ADVOGADOS DATIVOS | R21: 3922 - REPAROS DE BENS IMÓVEIS | AA21: 5220 - EQUIPAMENTOS DE SEGURANÇA ELETRÔNICA | AI21: 9323 - INDENIZAÇÃO DECORRENTE DE AUXÍLIO-SAÚDE
I22: 3021 - MATERIAL PARA MANUTENÇÃO E REPAROS DE BENS DE DOMÍNIO PÚBLICO OU DE TERCEIROS | O22: 3622 - TAXA DE CONDOMÍNIO | R22: 3923 - RECEPÇÕES, HOSPEDAGENS, HOMENAGENS E FESTIVIDADES | AA22: 5221 - MATERIAL DIDÁTICO | AI22: 9324 - AUXÍLIO-MORADIA DE CARÁTER INDENIZATÓRIO DEVIDO A MAGISTRADO
I23: 3022 - FERRAMENTAS, FERRAGENS E UTENSÍLIOS | O23: 3623 - GRATIFICAÇÃO POR ENCARGO DE CURSO OU CONCURSO | R23: 3924 - CURSOS, EXPOSIÇÕES, CONGRESSOS E CONFERÊNCIAS | AA23: 5222 - ESTRUTURAS E COMPONENTES | AI23: 9325 - AUXÍLIO-MORADIA DE CARÁTER INDENIZATÓRIO DEVIDO PELO TCE
I24: 3023 - MATERIAL PARA MANUTENÇÃO DE VEÍCULOS AUTOMOTORES | O24: 3624 - SERVIÇOS TÉCNICOS JUDICIAIS ? HONORÁRIOS PERICIAIS ? JUSTIÇA GRATUITA | R24: 3925 - ENCARGOS JUDICIAIS | AA24: 5223 - MÁQUINAS E EQUIPAMENTOS GRÁFICOS | AI24: 9326 - RESTITUICAO REFERENTE A TAXA DE INSCRIÇÃO, MATERIAL E SIMILARES
I25: 3024 - PEÇAS E ACESSÓRIOS PARA EQUIPAMENTOS E OUTROS MATERIAIS PERMANENTES | O25: 3625 - CONTRATAÇÃO PARA PRESTAÇÃO DE SERVIÇO POR CREDENCIADOS | R25: 3926 - ENCARGOS FINANCEIROS | AA25: 5224 - MÁQUINAS, INSTALAÇÕES E UTENSÍLIOS DE ESCRITÓRIO | AI25: 9327 - INDENIZAÇÃO DE TRANSPORTE DEVIDA AO OFICIAL DE JUSTIÇA E OFICIAL DE CARTÓRIO
I26: 3025 - MATERIAL DE SEGURANÇA, APETRECHOS OPERACIONAIS E POLICIAIS | O26: 3626 - SERVIÇOS DE ABASTECIMENTO E DISTRIBUIÇÃO DE ÁGUA | R26: 3928 - SERVIÇOS DE SAÚDE EXECUTADOS COM RECURSOS DO SUS | AA26: 5225 - APARELHOS E UTENSÍLIOS DOMÉSTICOS | AI26: 9328 - PENSÃO ACIDENTÁRIA
I27: 3026 - COMBUSTÍVEIS E LUBRIFICANTES PARA VEÍCULOS AUTOMOTORES | O27: 3627 - JUÍZES LEIGOS | R27: 3929 - SERVIÇOS MÉDICOS, ODONTOLÓGICOS E LABORATORIAIS | AA27: 5226 - EQUIPAMENTOS DE PROTEÇÃO, SEGURANÇA E SOCORRO | AI27: 9329 - DESPESA REFERENTE A RESSARCIMENTO SOBRE A REMUNERAÇÃO DOS PRESOS EM TRABALHO
I28: 3027 - COMBUSTÍVEIS E LUBRIFICANTES PARA EQUIPAMENTOS E OUTROS MATERIAIS PERMANENTES | O28: 3628 - SERVICOS TECNICOS JUDICIAIS - HONORARIOS PERICIAIS | R28: 3930 - MULTAS DE TRÂNSITO | AA28: 5299 - OUTROS MATERIAIS PERMANENTES | AI28: 9399 - OUTRAS INDENIZAÇÕES E RESTITUIÇÕES
I29: 3028 - ANIMAIS DESTINADOS A ESTUDOS, À PREPARAÇÃO DE PRODUTOS E AO ABATE | O29: 3629 - DIREITOS AUTORAIS | R29: 3931 - LOCAÇÃO DE SERVIÇOS GRÁFICOS
I30: 3029 - - SEMENTES, MUDAS DE PLANTAS E INSUMOS | O30: 3630 - SERVIÇOS MÉDICOS PRESTADOS POR CONTRATO | R30: 3933 - TAXA DE ADMINISTRAÇÃO
I31: 3030 - MATERIAIS PARA ACONDICIONAMENTO E EMBALAGEM | O31: 3631 - SERVIÇOS DE TREINAMENTO, CAPACITAÇÃO E APERFEIÇOAMENTO DE PESSOAL | R31: 3934 - SEGURO DE AERONAVES
I32: 3031 - LIVROS TÉCNICOS | O32: 3699 - OUTRAS DESPESAS PAGAS A PESSOAS FÍSICAS | R32: 3935 - REPARO E MANUTENÇÃO DE AERONAVES
I33: 3032 - MATERIAL CÍVICO E EDUCATIVO | R33: 3937 - TAXA DE CONDOMÍNIO
I34: 3033 - COMBUSTÍVEIS E LUBRIFICANTES PARA AERONAVES | R34: 3938 - SERVIÇOS DE IMPRESSÃO E ENCADERNAÇÃO
I35: 3034 - PEÇAS E ACESSÓRIOS PARA AERONAVES | R35: 3939 - SERVIÇOS DE PUBLICAÇÃO E DIVULGAÇÃO
I36: 3036 - MATERIAL BIBLIOGRÁFICO PARA BIBLIOTECAS PÚBLICAS | R36: 3941 - ANUIDADES, CERTIFICADOS E REGISTROS
I37: 3037 - MEDICAMENTOS ? DECISÃO JUDICIAL | R37: 3942 - SERVIÇOS GRÁFICOS DE SEGURANÇA
I38: 3038 - LEITE ? PROGRAMA LEITE PELA VIDA | R38: 3943 - SERVIÇOS DE ADMINISTRAÇÃO E GERENCIAMENTO DE FROTA DE VEÍCULOS
I39: 3039 - MATERIAL DE CONFECÇÃO EM GERAL | R39: 3944 - SERVIÇO DE SEGURANÇA FAZENDÁRIA
I40: 3040 - MATERIAL DE CAMA, MESA E BANHO | R40: 3946 - TERMO DE PARCERIA COM ORGANIZAÇÃO DA SOCIEDADE CIVIL DE INTERESSE PÚBLICO - OSCIP
...

Sheet DECRETO DIÁRIAS
G1: INDICE
B3: DECRETO 47045, DE 14/09/2016 DISPÕE SOBRE VIAGEM A SERVIÇO E CONCESSÃO DE DIÁRIA NO ÂMBITO DA ADMINISTRAÇÃO PÚBLICA DIRETA, AUTÁRQUICA E FUNDACIONAL DO PODER EXECUTIVO E DÁ OUTRAS PROVIDÊNCIAS.
B5: Tabela de Valores – Viagens Nacionais | F5: Tabela de Valores – Viagens ao Exterior
B6: DESTINO | C6: FAIXA I (R$) | D6: FAIXA II (R$) | F6: SERVIDORES | G6: LOCALIDADE/VALOR (U$)
B7: Capitais, inclusive Belo Horizonte | C7: 470 | D7: 665 | G7: América do Sul e América Central | H7: Demais Localidades no exterior
B8: Municípios especiais e municípios de outros Estados que não sejam capitais | C8: 362 | D8: 608 | F8: Governador do Estado; Vice-Governador do Estado | G8: 400 | H8: 550
B9: Demais municípios | C9: 258 | D9: 354 | F9: Secretário-Geral, Secretário de Estado, Secretário Adjunto de Estado | G9: 350 | H9: 450
B10: Faixa I: Servidor que exerça cargo efetivo que exija até o nível médio ou superior de escolaridade, servidor investido em cargo de provimento em comissão, servidor que exerça função pública que exija até o nível médio ou superior de escolaridade, e os membros de conselhos estaduais. | F10: Demais autoridades – Subsecretário, dirigente máximo de órgão autônomo, fundação e autarquia e seus respectivos Vices e servidor investido em cargo de provimento em comissão do Grupo de Direção e Assessoramento que esteja no nível DAD-8 a DAD-12 ou DAI-26 a DAI-40 e exerça atividades inerentes à chefia de Gabinete do Vice-Governador ou de Secretaria de Estado ou de entidades ou às assessorias especiais do Governador. | G10: 300 | H10: 400
B14: Faixa II: Secretário-Geral, Secretário de Estado, Secretário Adjunto, Subsecretário, dirigente máximo de órgão autônomo, fundação e autarquia e seus respectivos vices, Comandante de Aeronave, Comandante de Avião, Comandante de Avião a jato, Piloto de Helicóptero, Primeiro Oficial de Aeronave e servidor investido em cargo de provimento em comissão do Grupo de Direção e Assessoramento que esteja no nível DAD-8 a DAD-12 ou DAI-25 a DAI-40 e exerça atividades inerentes à chefia de gabinete do Vice-Governador, de Secretaria de Estado ou de entidades ou às assessorias especiais do Governador.
B15: Relação dos Municípios Especiais: Araxá, Caxambú, Contagem, Ipatinga, Juiz de Fora, Ouro Preto, Patos de Minas, Tiradentes, Uberlândia. | F15: Demais servidores | G15: 300 | H15: 300
B18: Link para o Decreto: | C18: https://www.almg.gov.br/consulte/legislacao/completa/completa.html?num=47045&ano=2016&tipo=DEC

Sheet BASE OBZ
F1: INDICE | H1: PROJETO ORÇAMENTO BASE-ZERO
A2: UNIDADE ORÇAMENTÁRIA | B2: N2 | C2: SUB SIGLA | D2: N3 | E2: PROGRAMAUO | F2: PROGRAMA | G2: prog cod | H2: AÇÃO | I2: ELEMENTO | J2: ELEMENTO_ITEM | K2: Agrupamento | L2: GRUPO | M2: FONTEUO | N2: FONTE | O2: DESCRIÇÃO DO ITEM | P2: NOVO? | Q2: PREMISSA VOLUME | R2: VOLUME | S2: PREMISSA DE PREÇO | T2: PREÇO UNITÁRIO | U2: FREQUÊNCIA PAGAMENTO | V2: VALOR TOTAL ITEM | W2: CLASSIFICAÇÃO CENÁRIO | X2: DESCRIÇÃO DO CENÁRIO | Y2: RISCO DE NÃO FAZER | Z2: BENEFICIO AO FAZER | AA2: PRIORIDADE N3 | AB2: PRIORIDADE N2 | AC2: PRIORIDADE N1 | AD2: PARECER DCMEFO | AE2: DELIBERAÇÃO COFIN
A3: SEE | B3: Subsecretaria de Gestão de Recursos Humanos | D3: Subsecretaria de Gestão de Recursos Humanos | F3: 169 - GESTÃO DO SISTEMA ESTADUAL DE EDUCAÇÃO | H3: 2128 - GESTÃO DO ÓRGÃO CENTRAL | I3: ELEMENTO | J3: 3924 - CURSOS, EXPOSICOES, CONGRESSOS E CONFERENCIAS | K3: =VLOOKUP(CONCATENATE(A3,LEFT(J3,4)),AGRUPAMENTO!$D$2:$E$6784,2,FALSE) -> Cursos de formação e capacitações | L3: 3 - Outras Despesas de Custeio | N3: 10 | O3: Verba necessária para funcionamento mínimo da Subsecretaria, Superintendência e Diretorias. | P3: NÃO | Q3: Valor estimado para 10 inscrições | R3: 10 | S3: Valor estimado para 10 inscrições | T3: 1000 | U3: 1 | V3: =R3*T3*U3 -> 10000 | W3: LIMIAR | X3: Aquisição de inscrições para participação em congressos e seminários. | Y3: Deixar de atender demandas da Secretaria | Z3: Possibilitar a participação em congressos e seminários de interesse da Secretaria. | AA3: 0 | AB3: 0 | AC3: 0 | AD3: 1 | AE3: 1
A4: SEE | B4: Subsecretaria de Gestão de Recursos Humanos | D4: Subsecretaria de Gestão de Recursos Humanos | F4: 169 - GESTÃO DO SISTEMA ESTADUAL DE EDUCAÇÃO | H4: 2128 - Gestão do Órgão Central | I4: ELEMENTO | J4: 1401 - DIARIAS - CIVIL | K4: =VLOOKUP(CONCATENATE(A4,LEFT(J4,4)),AGRUPAMENTO!$D$2:$E$6784,2,FALSE) -> Diárias e viagens | L4: 3 - Outras Despesas de Custeio | N4: 10 | O4: Diárias para atender demandas da SG. | P4: NÃO | Q4: Conforme demanda. | R4: 200 | S4: Decreto de diárias | T4: 500 | U4: 1 | V4: =R4*T4*U4 -> 100000 | W4: LIMIAR | X4: Viagens à serviço | Y4: Deixar de atender demandas da Secretaria | Z4: Permitir o atendimento às demandas da Secretaria, e garantir estrutura mínima de atuação. | AA4: 0 | AB4: 0 | AC4: 0 | AD4: 1 | AE4: 1
A5: SEE | B5: Subsecretaria de Gestão de Recursos Humanos | D5: Subsecretaria de Gestão de Recursos Humanos | F5: 169 - GESTÃO DO SISTEMA ESTADUAL DE EDUCAÇÃO | H5: 2128 - Gestão do Órgão Central | I5: ELEMENTO | J5: 3301 - PASSAGENS - PESSOA FISICA | K5: =VLOOKUP(CONCATENATE(A5,LEFT(J5,4)),AGRUPAMENTO!$D$2:$E$6784,2,FALSE) -> Diárias e viagens | L5: 3 - Outras Despesas de Custeio | N5: 10 | O5: Despesas com passagens rodoviárias | P5: NÃO | Q5: Conforme demanda. | R5: 150 | S5: Passagens ida e volta | T5: 300 | U5: 1 | V5: =R5*T5*U5 -> 45000 | W5: LIMIAR | X5: Atendimento de demandas de projetos da SEE | Y5: Deixar de atender demandas da Secretaria | Z5: Permitir o atendimento às demandas da Secretaria | AA5: 0 | AB5: 0 | AC5: 0 | AD5: 1 | AE5: 1
A6: SEE | B6: Subsecretaria de Gestão de Recursos Humanos | D6: Subsecretaria de Gestão de Recursos Humanos | F6: 169 - GESTÃO DO SISTEMA ESTADUAL DE EDUCAÇÃO | H6: 2128 - Gestão do Órgão Central | I6: ELEMENTO | J6: 1401 - DIARIAS - CIVIL | K6: =VLOOKUP(CONCATENATE(A6,LEFT(J6,4)),AGRUPAMENTO!$D$2:$E$6784,2,FALSE) -> Diárias e viagens | L6: 3 - Outras Despesas de Custeio | N6: 10 | O6: Encontro gerencial DIPEs | P6: NÃO | Q6: Valor previsto para 2 pessoas, 2 vezes ano | R6: 1 | S6: Decreto de diárias | T6: 149000 | U6: 2 | V6: =R6*T6*U6 -> 298000 | W6: LIMIAR | X6: Promover o alinhamento das ações e diretrizes da SEE/SG, para o exercício de 20256 | Y6: Deixar de atender demandas da Secretaria | Z6: Permitir o atendimento às demandas da Secretaria | AA6: 0 | AB6: 0 | AC6: 0 | AD6: 1 | AE6: 1
